### Error 实例对象
JavaScript 解析或运行时，一旦发生错误，引擎就会抛出一个错误对象。JavaScript 原生提供`Error`构造函数，所有抛出的错误都是这个构造函数的实例。
```js
var err = new Error('出错了');
console.log(err.message);
```

JavaScript 语言标准只提到，`Error` 实例对象必须有 `message`属性，表示出错时的提示信息，没有提到其他属性。大多数JavaScript引擎，对`Error`实例还提供`name`和`stack`属性，分别表示错误的名称和错误的堆栈，但他们时非标准的，不是每种实现都有。

- message：错误提示信息
- name：错误名称（非标准属性）
- stack：错误的堆栈（非标准属性）

`stack`属性用来查看错误发生时的堆栈。
```js
function throwit() {
    throw new Error('');
}

function catchit() {
    try {
        throwit();
    } catch (error) {
        console.log(error.stack);
    }
}
catchit();
// Error
    // at throwit (20210803.js:5)
    // at catchit (20210803.js:10)
    // at 20210803.js:15
```

### 原生错误类型
#### SyntaxError 对象
`SyntaxError`对象是解析代码时发生的语法错误。

```js
// 变量名错误
var 1a;
// Uncaught SyntaxError: Invalid or unexpected token

// 缺少括号
console.log 'hello');
// Uncaught SyntaxError: Unexpected string
```

#### ReferenceError 对象
`ReferenceError`对象是引用一个不存在的变量时发生的错误。
```js
// 使用一个不存在的变量
unknownVariable
// Uncaught ReferenceError: unknownVariable is not defined

// 等号左侧不是变量
console.log() = 1
// Uncaught ReferenceError: Invalid left-hand side in assignment
```

#### RangeError 对象
`RangeError` 对象是一个值超出有效范围时发生的错误。
- 数组长度为负数
- `Number`对象的方法参数超出范围，以及函数堆栈超出最大值。
```js
// 数组长度不得为负数
new Array(-1)
// Uncaught RangeError: Invalid array length
```

#### TypeError 对象
`TypeError`对象是变量或参数不是预期类型时发生的错误。
```js
new 123 // Uncaught TypeError: 123 is not a constructor

var obj = {};
// obj.unknownMethod的值是undefined，而不是一个函数。
obj.unknownMethod()
// Uncaught TypeError: obj.unknownMethod is not a function
```

#### URIError 对象
`URIError`对象是 `URI` 相关函数的参数不正确时抛出的错误，主要涉及`encodeURI()`、`decodeURI()`、`encodeURIComponent()`、`decodeURIComponent()`、`escape()`和`unescape()`这六个函数。
```js
decodeURI('%2')
// URIError: URI malformed
```

#### EvalError 对象
`eval`函数没有被正确执行时，会抛出`EvalError`错误。该错误类型已经不再使用了，只是为了保证与以前代码兼容，才继续保留。

### 自定义错误
```js
function UserError(message) {
    this.message = message || '默认信息';
    this.name = 'UserError';
}
UserError.prototypr = new Error();
UserError.prototype.constructor = UserError;

var err = new UserError('自定义错误');
console.log(err.message);
console.log(err.stack); // undefined
```

### throw 语句
`throw`语句的作用是手动中断程序执行，抛出一个错误。
```js
var x = -1;

if (x <= 0) {
  throw new Error('x 必须为正数');
}
// Uncaught Error: x 必须为正数
```

`throw`也可以抛出自定义错误。
```js
function UserError(message) {
    this.message = message || '默认信息';
    this.name = 'UserError';
}

throw new UserError('出错了！');
// Uncaught UserError {message: "出错了！", name: "UserError"}
```

*`throw`可以抛出任何类型的值。*

```js
// 抛出一个字符串
throw 'Error！';
// Uncaught Error！

// 抛出一个数值
throw 42;
// Uncaught 42

// 抛出一个布尔值
throw true;
// Uncaught true

// 抛出一个对象
throw {
  toString: function () {
    return 'Error!';
  }
};
// Uncaught {toString: ƒ}
```

### try...catch 结构
```js
try {
    throw new Error('出错了！');
} catch (e) {
    console.log(e.name + ": " + e.message);
    console.log(e.stack);
    // Error: 出错了！
    // at 20210803.js:52
}
```

为了捕捉不同类型的错误，`catch`代码块之中可以加入判断语句。
```js
try {
  foo.bar();
} catch (e) {
  if (e instanceof EvalError) {
    console.log(e.name + ": " + e.message);
  } else if (e instanceof RangeError) {
    console.log(e.name + ": " + e.message);
  }
  // ...
}
```

### finally 代码块
`try...catch`结构允许在最后添加一个`finally`代码块，表示不管是否出现错误，都必需在最后运行的语句。
```js
function cleanUp() {
    try {
        throw new Error('出错了。。。');
        console.log('此行不会执行');
    } finally {
        console.log('完成清理工作');
    }
}
cleanUp();
// 完成清理工作
// Uncaught Error: 出错了。。。
// at cleanUp (20210803.js:62)
// at 20210803.js:68
```

*`return`语句的执行是排在`finally`代码之前，只是等`finally`代码执行完毕后才返回。*
```js
var count = 0;
function countUp() {
    try {
        return count;
    } finally {
        count++;
    }
}
countUp();
// 0
console.log(count); // 1
```

```js
// try...catch...finally这三者之间的执行顺序
function f() {
  try {
    console.log(0);
    throw 'bug';
  } catch(e) {
    console.log(1);
    return true; // 这句原本会延迟到 finally 代码块结束再执行
    console.log(2); // 不会运行
  } finally {
    console.log(3);
    return false; // 这句会覆盖掉前面那句 return
    console.log(4); // 不会运行
  }

  console.log(5); // 不会运行
}

var result = f();
// 0
// 1
// 3

result
// false
```
*`catch`代码块之中，触发转入`finally`代码块的标志，不仅有`return`语句，还有`throw`语句。*

```js
function f() {
  try {
    throw '出错了！';
  } catch(e) {
    console.log('捕捉到内部错误');
    throw e; // 这句原本会等到finally结束再执行
  } finally {
    return false; // 直接返回
  }
}

try {
  f();
} catch(e) {
  // 此处不会执行
  console.log('caught outer "bogus"');
}

//  捕捉到内部错误
```